<?xml version="1.0"?>
<robot xmlns:xacro="http://www.ros.org/xacro"
      xmlns:gz="http://gazebosim.org/schema">

  <xacro:include filename="inertial_macros_mecanum_sphere.xacro"/>

  <!-- Define Materials -->
  <material name="white">
        <color rgba="1 1 1 1" />
    </material>

    <material name="orange">
        <color rgba="1 0.3 0.1 1"/>
    </material>

    <material name="blue">
        <color rgba="0.2 0.2 1 1"/>
    </material>

    <material name="black">
        <color rgba="0 0 0 1"/>
    </material>

    <material name="red">
        <color rgba="1 0 0 1"></color>
    </material>

  <!-- BASE LINK -->
  <link name="base_link"/>

  <!-- BASE_FOOTPRINT LINK -->
  <joint name="base_footprint_joint" type="fixed">
    <parent link="base_link"/>
    <child link="base_footprint"/>
    <origin xyz="0 0 0" rpy="0 0 0"/>
  </joint>
  <link name="base_footprint"/>

  <!-- CHASSIS -->
  <joint name="chassis_joint" type="fixed">
    <parent link="base_link"/>
    <child link="chassis"/>
    <origin xyz="0 0 0"/>
  </joint>

  <link name="chassis">
    <visual>
      <origin xyz="0 0 0.075"/>
      <geometry>
        <box size="0.3 0.3 0.15"/>
      </geometry>
      <material name="white"/>
    </visual>
    <collision>
      <origin xyz="0 0 0.075"/>
      <geometry>
        <box size="0.3 0.3 0.15"/>
      </geometry>
    </collision>
    <xacro:inertial_box mass="6.0" x="0.3" y="0.3" z="0.15">
      <origin xyz="0 0 0.075" rpy="0 0 0"/>
    </xacro:inertial_box>
  </link>

  <!-- FRONT LEFT WHEEL -->
  <joint name="front_left_wheel_joint" type="continuous">
    <parent link="base_link"/>
    <child link="front_left_wheel"/>
    <origin xyz="0.15 0.17 0.025" rpy="-1.5708 0 0"/>
    <axis xyz="0 0 1"/>
  </joint>

  <link name="front_left_wheel">
    <visual>
      <geometry>
        <sphere radius="0.05"/>
      </geometry>
      <material name="blue"/>
    </visual>
    <collision>
      <geometry>
        <sphere radius="0.05"/>
      </geometry>
    </collision>
    <xacro:inertial_sphere mass="1" radius="0.05">
      <origin xyz="0 0 0" rpy="0 0 0"/>
    </xacro:inertial_sphere>
  </link>

  <!-- FRONT RIGHT WHEEL -->
  <joint name="front_right_wheel_joint" type="continuous">
    <parent link="base_link"/>
    <child link="front_right_wheel"/>
    <origin xyz="0.15 -0.17 0.025" rpy="-1.5708 0 0"/>
    <axis xyz="0 0 1"/>
  </joint>

  <link name="front_right_wheel">
    <visual>
      <geometry>
        <sphere radius="0.05"/>
      </geometry>
      <material name="blue"/>
    </visual>
    <collision>
      <geometry>
        <sphere radius="0.05"/>
      </geometry>
    </collision>
    <xacro:inertial_sphere mass="1" radius="0.05">
      <origin xyz="0 0 0" rpy="0 0 0"/>
    </xacro:inertial_sphere>
  </link>

  <!-- REAR LEFT WHEEL -->
  <joint name="rear_left_wheel_joint" type="continuous">
    <parent link="base_link"/>
    <child link="rear_left_wheel"/>
    <origin xyz="-0.15 0.17 0.025" rpy="-1.5708 0 0"/>
    <axis xyz="0 0 1"/>
  </joint>

  <link name="rear_left_wheel">
    <visual>
      <geometry>
        <sphere radius="0.05"/>
      </geometry>
      <material name="blue"/>
    </visual>
    <collision>
      <geometry>
        <sphere radius="0.05"/>
      </geometry>>
    </collision>
    <xacro:inertial_sphere mass="1" radius="0.05">
      <origin xyz="0 0 0" rpy="0 0 0"/>
    </xacro:inertial_sphere>
  </link>

  <!-- REAR RIGHT WHEEL -->
  <joint name="rear_right_wheel_joint" type="continuous">
    <parent link="base_link"/>
    <child link="rear_right_wheel"/>
    <origin xyz="-0.15 -0.17 0.025" rpy="-1.5708 0 0"/> <!-- No rotation needed for spheres -->
    <axis xyz="0 0 1"/>
  </joint>

<link name="rear_right_wheel">
  <visual>
    <geometry>
      <sphere radius="0.05"/>
    </geometry>
    <material name="blue"/>
  </visual>
  <collision>
    <geometry>
      <sphere radius="0.05"/>
    </geometry>
  </collision>
  <xacro:inertial_sphere mass="1" radius="0.05">
    <origin xyz="0 0 0" rpy="0 0 0"/>
  </xacro:inertial_sphere>
</link>

  <gazebo reference='front_left_wheel'>
    <collision>
      <surface>
        <friction>
          <ode>
            <mu>1.0</mu>
            <mu2>0.0</mu2>
            <fdir1 gz:expressed_in="base_link">1 -1 0</fdir1>
          </ode>
        </friction>
      </surface>
    </collision>
  </gazebo>
  <gazebo reference='front_right_wheel'>
    <collision>
      <surface>
        <friction>
          <ode>
            <mu>1.0</mu>
            <mu2>0.0</mu2>
            <fdir1 gz:expressed_in="base_link">1 1 0</fdir1>
          </ode>
        </friction>
      </surface>
    </collision>
  </gazebo>
  <gazebo reference='rear_left_wheel'>
    <collision>
      <surface>
        <friction>
          <ode>
            <mu>1.0</mu>
            <mu2>0.0</mu2>
            <fdir1 gz:expressed_in="base_link">1 1 0</fdir1>
          </ode>
        </friction>
      </surface>
    </collision>
  </gazebo>
  <gazebo reference='rear_right_wheel'>
    <collision>
      <surface>
        <friction>
          <ode>
            <mu>1.0</mu>
            <mu2>0.0</mu2>
            <fdir1 gz:expressed_in="base_link">1 -1 0</fdir1>
          </ode>
        </friction>
      </surface>
    </collision>
  </gazebo>

</robot>
